<?xml version="1.0" ?>
<!-- =================================================================================== -->
<!-- |    This document was autogenerated by xacro from main.urdf.xacro                | -->
<!-- |    EDITING THIS FILE BY HAND IS NOT RECOMMENDED                                 | -->
<!-- =================================================================================== -->
<robot name="open_base" xmlns:xacro="http://www.ros.org/wiki/xacro">
  <link name="origin_link"/>
  <link name="base_link">
    <inertial>
      <mass value="0.660"/>
      <inertia ixx="0.0029" ixy="3.82830626450116e-06" ixz="1.95168554660843e-06" iyy="0.00368658386788590" iyz="0.000245762249215231" izz="0.00610900095537055"/>
    </inertial>
    <visual>
      <geometry>
        <mesh filename="package://erobotica_omnibot/mesh/chassi.stl"/>
      </geometry>
      <material name="base_material">
        <color rgba="1 1 1 1"/>
      </material>
    </visual>
    <collision>
      <geometry>
        <mesh filename="package://erobotica_omnibot/mesh/chassi.stl"/>
      </geometry>
    </collision>
  </link>
  <joint name="base_joint" type="fixed">
    <parent link="origin_link"/>
    <child link="base_link"/>
    <origin xyz="0 0 0.020269"/>
  </joint>
  <link name="rim_left_link">
    <inertial>
      <origin xyz="0 0 -0.000343"/>
      <mass value="0.083"/>
      <inertia ixx="0.1449e-04" ixy="0" ixz="0" iyy="0.1449e-04" iyz="0" izz="0.2283e-04"/>
    </inertial>
    <visual>
      <geometry>
        <mesh filename="package://erobotica_omnibot/mesh/roda.stl"/>
      </geometry>
      <material name="rim_left_material">
        <color rgba="0.3 0 0 1"/>
      </material>
    </visual>
    <collision>
      <!---test -->
      <geometry>
        <!---<cylinder length="0.6" radius="0.029"/> -->
        <mesh filename="package://erobotica_omnibot/mesh/roda.stl"/>
      </geometry>
    </collision>
  </link>
  <joint name="rim_left_joint" type="continuous">
    <parent link="base_link"/>
    <child link="rim_left_link"/>
    <axis xyz="0 0 1"/>
    <origin rpy="1.570796326794896 0 1.047197551196597" xyz="-0.0893842140 0.051606 0.020269"/>
  </joint>
  <link name="roller_upfront_rim_left_link">
    <inertial>
      <mass value="0.001"/>
      <inertia ixx="3.976186554728152e-08" ixy="0" ixz="0" iyy="3.976186554728152e-08" iyz="0" izz="2.092071223656384e-08"/>
    </inertial>
    <visual>
      <geometry>
        <mesh filename="package://erobotica_omnibot/mesh/rolamento.stl"/>
      </geometry>
      <material name="roller_material">
        <color rgba="0.1 0.1 0.1 1"/>
      </material>
    </visual>
    <collision>
      <geometry>
        <mesh filename="package://erobotica_omnibot/mesh/rolamento.stl"/>
      </geometry>
    </collision>
  </link>
  <gazebo reference="roller_upfront_rim_left_link">
    <material>Gazebo/Black</material>
  </gazebo>
  <joint name="roller_upfront_rim_left_joint" type="continuous">
    <parent link="rim_left_link"/>
    <child link="roller_upfront_rim_left_link"/>
    <axis xyz="0 0 1"/>
    <origin rpy="-1.570796326794896 0 1.570796326794896" xyz="0 0.02406 0.005"/>
  </joint>
  <link name="roller_rightupfront_rim_left_link">
    <inertial>
      <mass value="0.001"/>
      <inertia ixx="3.976186554728152e-08" ixy="0" ixz="0" iyy="3.976186554728152e-08" iyz="0" izz="2.092071223656384e-08"/>
    </inertial>
    <visual>
      <geometry>
        <mesh filename="package://erobotica_omnibot/mesh/rolamento.stl"/>
      </geometry>
      <material name="roller_material">
        <color rgba="0.1 0.1 0.1 1"/>
      </material>
    </visual>
    <collision>
      <geometry>
        <mesh filename="package://erobotica_omnibot/mesh/rolamento.stl"/>
      </geometry>
    </collision>
  </link>
  <gazebo reference="roller_rightupfront_rim_left_link">
    <material>Gazebo/Black</material>
  </gazebo>
  <joint name="roller_rightupfront_rim_left_joint" type="continuous">
    <parent link="rim_left_link"/>
    <child link="roller_rightupfront_rim_left_link"/>
    <axis xyz="0 0 1"/>
    <origin rpy="-1.570796326794896 0 -2.82743" xyz=" 0.02288 0.00743 0.005"/>
  </joint>
  <link name="roller_leftupfront_rim_left_link">
    <inertial>
      <mass value="0.001"/>
      <inertia ixx="3.976186554728152e-08" ixy="0" ixz="0" iyy="3.976186554728152e-08" iyz="0" izz="2.092071223656384e-08"/>
    </inertial>
    <visual>
      <geometry>
        <mesh filename="package://erobotica_omnibot/mesh/rolamento.stl"/>
      </geometry>
      <material name="roller_material">
        <color rgba="0.1 0.1 0.1 1"/>
      </material>
    </visual>
    <collision>
      <geometry>
        <mesh filename="package://erobotica_omnibot/mesh/rolamento.stl"/>
      </geometry>
    </collision>
  </link>
  <gazebo reference="roller_leftupfront_rim_left_link">
    <material>Gazebo/Black</material>
  </gazebo>
  <joint name="roller_leftupfront_rim_left_joint" type="continuous">
    <parent link="rim_left_link"/>
    <child link="roller_leftupfront_rim_left_link"/>
    <axis xyz="0 0 1"/>
    <origin rpy="-1.570796326794896 0 2.82743" xyz=" -0.02288  0.00743 0.005"/>
  </joint>
  <link name="roller_rightdownfront_rim_left_link">
    <inertial>
      <mass value="0.001"/>
      <inertia ixx="3.976186554728152e-08" ixy="0" ixz="0" iyy="3.976186554728152e-08" iyz="0" izz="2.092071223656384e-08"/>
    </inertial>
    <visual>
      <geometry>
        <mesh filename="package://erobotica_omnibot/mesh/rolamento.stl"/>
      </geometry>
      <material name="roller_material">
        <color rgba="0.1 0.1 0.1 1"/>
      </material>
    </visual>
    <collision>
      <geometry>
        <mesh filename="package://erobotica_omnibot/mesh/rolamento.stl"/>
      </geometry>
    </collision>
  </link>
  <gazebo reference="roller_rightdownfront_rim_left_link">
    <material>Gazebo/Black</material>
  </gazebo>
  <joint name="roller_rightdownfront_rim_left_joint" type="continuous">
    <parent link="rim_left_link"/>
    <child link="roller_rightdownfront_rim_left_link"/>
    <axis xyz="0 0 1"/>
    <origin rpy="-1.570796326794896 0 -0.959931" xyz="0.01414 -0.01947 0.005"/>
  </joint>
  <link name="roller_lefttdownfront_rim_left_link">
    <inertial>
      <mass value="0.001"/>
      <inertia ixx="3.976186554728152e-08" ixy="0" ixz="0" iyy="3.976186554728152e-08" iyz="0" izz="2.092071223656384e-08"/>
    </inertial>
    <visual>
      <geometry>
        <mesh filename="package://erobotica_omnibot/mesh/rolamento.stl"/>
      </geometry>
      <material name="roller_material">
        <color rgba="0.1 0.1 0.1 1"/>
      </material>
    </visual>
    <collision>
      <geometry>
        <mesh filename="package://erobotica_omnibot/mesh/rolamento.stl"/>
      </geometry>
    </collision>
  </link>
  <gazebo reference="roller_lefttdownfront_rim_left_link">
    <material>Gazebo/Black</material>
  </gazebo>
  <joint name="roller_lefttdownfront_rim_left_joint" type="continuous">
    <parent link="rim_left_link"/>
    <child link="roller_lefttdownfront_rim_left_link"/>
    <axis xyz="0 0 1"/>
    <origin rpy="-1.570796326794896 0 0.959931" xyz="-0.01414 -0.01947 0.005"/>
  </joint>
  <!---Back part of the wheel -->
  <link name="roller_upback_rim_left_link">
    <inertial>
      <mass value="0.001"/>
      <inertia ixx="3.976186554728152e-08" ixy="0" ixz="0" iyy="3.976186554728152e-08" iyz="0" izz="2.092071223656384e-08"/>
    </inertial>
    <visual>
      <geometry>
        <mesh filename="package://erobotica_omnibot/mesh/rolamento.stl"/>
      </geometry>
      <material name="roller_material">
        <color rgba="0.1 0.1 0.1 1"/>
      </material>
    </visual>
    <collision>
      <geometry>
        <mesh filename="package://erobotica_omnibot/mesh/rolamento.stl"/>
      </geometry>
    </collision>
  </link>
  <gazebo reference="roller_upback_rim_left_link">
    <material>Gazebo/Black</material>
  </gazebo>
  <joint name="roller_upback_rim_left_joint" type="continuous">
    <parent link="rim_left_link"/>
    <child link="roller_upback_rim_left_link"/>
    <axis xyz="0 0 1"/>
    <origin rpy="-1.570796326794896 0 1.570796326794896" xyz="0 -0.02406 -0.006"/>
  </joint>
  <link name="roller_rightupback_rim_left_link">
    <inertial>
      <mass value="0.001"/>
      <inertia ixx="3.976186554728152e-08" ixy="0" ixz="0" iyy="3.976186554728152e-08" iyz="0" izz="2.092071223656384e-08"/>
    </inertial>
    <visual>
      <geometry>
        <mesh filename="package://erobotica_omnibot/mesh/rolamento.stl"/>
      </geometry>
      <material name="roller_material">
        <color rgba="0.1 0.1 0.1 1"/>
      </material>
    </visual>
    <collision>
      <geometry>
        <mesh filename="package://erobotica_omnibot/mesh/rolamento.stl"/>
      </geometry>
    </collision>
  </link>
  <gazebo reference="roller_rightupback_rim_left_link">
    <material>Gazebo/Black</material>
  </gazebo>
  <joint name="roller_rightupback_rim_left_joint" type="continuous">
    <parent link="rim_left_link"/>
    <child link="roller_rightupback_rim_left_link"/>
    <axis xyz="0 0 1"/>
    <origin rpy="-1.570796326794896 0 -2.82743" xyz=" -0.02288 -0.00743 -0.006"/>
  </joint>
  <link name="roller_leftupback_rim_left_link">
    <inertial>
      <mass value="0.001"/>
      <inertia ixx="3.976186554728152e-08" ixy="0" ixz="0" iyy="3.976186554728152e-08" iyz="0" izz="2.092071223656384e-08"/>
    </inertial>
    <visual>
      <geometry>
        <mesh filename="package://erobotica_omnibot/mesh/rolamento.stl"/>
      </geometry>
      <material name="roller_material">
        <color rgba="0.1 0.1 0.1 1"/>
      </material>
    </visual>
    <collision>
      <geometry>
        <mesh filename="package://erobotica_omnibot/mesh/rolamento.stl"/>
      </geometry>
    </collision>
  </link>
  <gazebo reference="roller_leftupback_rim_left_link">
    <material>Gazebo/Black</material>
  </gazebo>
  <joint name="roller_leftupback_rim_left_joint" type="continuous">
    <parent link="rim_left_link"/>
    <child link="roller_leftupback_rim_left_link"/>
    <axis xyz="0 0 1"/>
    <origin rpy="-1.570796326794896 0 2.82743" xyz=" 0.02288 -0.00743 -0.006"/>
  </joint>
  <link name="roller_rightdownback_rim_left_link">
    <inertial>
      <mass value="0.001"/>
      <inertia ixx="3.976186554728152e-08" ixy="0" ixz="0" iyy="3.976186554728152e-08" iyz="0" izz="2.092071223656384e-08"/>
    </inertial>
    <visual>
      <geometry>
        <mesh filename="package://erobotica_omnibot/mesh/rolamento.stl"/>
      </geometry>
      <material name="roller_material">
        <color rgba="0.1 0.1 0.1 1"/>
      </material>
    </visual>
    <collision>
      <geometry>
        <mesh filename="package://erobotica_omnibot/mesh/rolamento.stl"/>
      </geometry>
    </collision>
  </link>
  <gazebo reference="roller_rightdownback_rim_left_link">
    <material>Gazebo/Black</material>
  </gazebo>
  <joint name="roller_rightdownback_rim_left_joint" type="continuous">
    <parent link="rim_left_link"/>
    <child link="roller_rightdownback_rim_left_link"/>
    <axis xyz="0 0 1"/>
    <origin rpy="-1.570796326794896 0 -0.959931" xyz="-0.01414 0.01947 -0.006"/>
  </joint>
  <link name="roller_lefttdownback_rim_left_link">
    <inertial>
      <mass value="0.001"/>
      <inertia ixx="3.976186554728152e-08" ixy="0" ixz="0" iyy="3.976186554728152e-08" iyz="0" izz="2.092071223656384e-08"/>
    </inertial>
    <visual>
      <geometry>
        <mesh filename="package://erobotica_omnibot/mesh/rolamento.stl"/>
      </geometry>
      <material name="roller_material">
        <color rgba="0.1 0.1 0.1 1"/>
      </material>
    </visual>
    <collision>
      <geometry>
        <mesh filename="package://erobotica_omnibot/mesh/rolamento.stl"/>
      </geometry>
    </collision>
  </link>
  <gazebo reference="roller_lefttdownback_rim_left_link">
    <material>Gazebo/Black</material>
  </gazebo>
  <joint name="roller_lefttdownback_rim_left_joint" type="continuous">
    <parent link="rim_left_link"/>
    <child link="roller_lefttdownback_rim_left_link"/>
    <axis xyz="0 0 1"/>
    <origin rpy="-1.570796326794896 0 0.959931" xyz="0.01414  0.01947 -0.006"/>
  </joint>
  <transmission name="rim_left_transmission">
    <type>transmission_interface/SimpleTransmission</type>
    <joint name="rim_left_joint">
      <hardwareInterface>hardware_interface/VelocityJointInterface</hardwareInterface>
    </joint>
    <actuator name="rim_left_motor">
      <hardwareInterface>hardware_interface/VelocityJointInterface</hardwareInterface>
      <mechanicalReduction>1</mechanicalReduction>
    </actuator>
  </transmission>
  <link name="rim_back_link">
    <inertial>
      <origin xyz="0 0 -0.000343"/>
      <mass value="0.083"/>
      <inertia ixx="0.1449e-04" ixy="0" ixz="0" iyy="0.1449e-04" iyz="0" izz="0.2283e-04"/>
    </inertial>
    <visual>
      <geometry>
        <mesh filename="package://erobotica_omnibot/mesh/roda.stl"/>
      </geometry>
      <material name="rim_back_material">
        <color rgba="0 0.3 0 1"/>
      </material>
    </visual>
    <collision>
      <!---test -->
      <geometry>
        <!---<cylinder length="0.6" radius="0.029"/> -->
        <mesh filename="package://erobotica_omnibot/mesh/roda.stl"/>
      </geometry>
    </collision>
  </link>
  <joint name="rim_back_joint" type="continuous">
    <parent link="base_link"/>
    <child link="rim_back_link"/>
    <axis xyz="0 0 1"/>
    <origin rpy="1.570796326794896 0 3.141592653589793" xyz="0 -0.103212  0.020269"/>
  </joint>
  <link name="roller_upfront_rim_back_link">
    <inertial>
      <mass value="0.001"/>
      <inertia ixx="3.976186554728152e-08" ixy="0" ixz="0" iyy="3.976186554728152e-08" iyz="0" izz="2.092071223656384e-08"/>
    </inertial>
    <visual>
      <geometry>
        <mesh filename="package://erobotica_omnibot/mesh/rolamento.stl"/>
      </geometry>
      <material name="roller_material">
        <color rgba="0.1 0.1 0.1 1"/>
      </material>
    </visual>
    <collision>
      <geometry>
        <mesh filename="package://erobotica_omnibot/mesh/rolamento.stl"/>
      </geometry>
    </collision>
  </link>
  <gazebo reference="roller_upfront_rim_back_link">
    <material>Gazebo/Black</material>
  </gazebo>
  <joint name="roller_upfront_rim_back_joint" type="continuous">
    <parent link="rim_back_link"/>
    <child link="roller_upfront_rim_back_link"/>
    <axis xyz="0 0 1"/>
    <origin rpy="-1.570796326794896 0 1.570796326794896" xyz="0 0.02406 0.005"/>
  </joint>
  <link name="roller_rightupfront_rim_back_link">
    <inertial>
      <mass value="0.001"/>
      <inertia ixx="3.976186554728152e-08" ixy="0" ixz="0" iyy="3.976186554728152e-08" iyz="0" izz="2.092071223656384e-08"/>
    </inertial>
    <visual>
      <geometry>
        <mesh filename="package://erobotica_omnibot/mesh/rolamento.stl"/>
      </geometry>
      <material name="roller_material">
        <color rgba="0.1 0.1 0.1 1"/>
      </material>
    </visual>
    <collision>
      <geometry>
        <mesh filename="package://erobotica_omnibot/mesh/rolamento.stl"/>
      </geometry>
    </collision>
  </link>
  <gazebo reference="roller_rightupfront_rim_back_link">
    <material>Gazebo/Black</material>
  </gazebo>
  <joint name="roller_rightupfront_rim_back_joint" type="continuous">
    <parent link="rim_back_link"/>
    <child link="roller_rightupfront_rim_back_link"/>
    <axis xyz="0 0 1"/>
    <origin rpy="-1.570796326794896 0 -2.82743" xyz=" 0.02288 0.00743 0.005"/>
  </joint>
  <link name="roller_leftupfront_rim_back_link">
    <inertial>
      <mass value="0.001"/>
      <inertia ixx="3.976186554728152e-08" ixy="0" ixz="0" iyy="3.976186554728152e-08" iyz="0" izz="2.092071223656384e-08"/>
    </inertial>
    <visual>
      <geometry>
        <mesh filename="package://erobotica_omnibot/mesh/rolamento.stl"/>
      </geometry>
      <material name="roller_material">
        <color rgba="0.1 0.1 0.1 1"/>
      </material>
    </visual>
    <collision>
      <geometry>
        <mesh filename="package://erobotica_omnibot/mesh/rolamento.stl"/>
      </geometry>
    </collision>
  </link>
  <gazebo reference="roller_leftupfront_rim_back_link">
    <material>Gazebo/Black</material>
  </gazebo>
  <joint name="roller_leftupfront_rim_back_joint" type="continuous">
    <parent link="rim_back_link"/>
    <child link="roller_leftupfront_rim_back_link"/>
    <axis xyz="0 0 1"/>
    <origin rpy="-1.570796326794896 0 2.82743" xyz=" -0.02288  0.00743 0.005"/>
  </joint>
  <link name="roller_rightdownfront_rim_back_link">
    <inertial>
      <mass value="0.001"/>
      <inertia ixx="3.976186554728152e-08" ixy="0" ixz="0" iyy="3.976186554728152e-08" iyz="0" izz="2.092071223656384e-08"/>
    </inertial>
    <visual>
      <geometry>
        <mesh filename="package://erobotica_omnibot/mesh/rolamento.stl"/>
      </geometry>
      <material name="roller_material">
        <color rgba="0.1 0.1 0.1 1"/>
      </material>
    </visual>
    <collision>
      <geometry>
        <mesh filename="package://erobotica_omnibot/mesh/rolamento.stl"/>
      </geometry>
    </collision>
  </link>
  <gazebo reference="roller_rightdownfront_rim_back_link">
    <material>Gazebo/Black</material>
  </gazebo>
  <joint name="roller_rightdownfront_rim_back_joint" type="continuous">
    <parent link="rim_back_link"/>
    <child link="roller_rightdownfront_rim_back_link"/>
    <axis xyz="0 0 1"/>
    <origin rpy="-1.570796326794896 0 -0.959931" xyz="0.01414 -0.01947 0.005"/>
  </joint>
  <link name="roller_lefttdownfront_rim_back_link">
    <inertial>
      <mass value="0.001"/>
      <inertia ixx="3.976186554728152e-08" ixy="0" ixz="0" iyy="3.976186554728152e-08" iyz="0" izz="2.092071223656384e-08"/>
    </inertial>
    <visual>
      <geometry>
        <mesh filename="package://erobotica_omnibot/mesh/rolamento.stl"/>
      </geometry>
      <material name="roller_material">
        <color rgba="0.1 0.1 0.1 1"/>
      </material>
    </visual>
    <collision>
      <geometry>
        <mesh filename="package://erobotica_omnibot/mesh/rolamento.stl"/>
      </geometry>
    </collision>
  </link>
  <gazebo reference="roller_lefttdownfront_rim_back_link">
    <material>Gazebo/Black</material>
  </gazebo>
  <joint name="roller_lefttdownfront_rim_back_joint" type="continuous">
    <parent link="rim_back_link"/>
    <child link="roller_lefttdownfront_rim_back_link"/>
    <axis xyz="0 0 1"/>
    <origin rpy="-1.570796326794896 0 0.959931" xyz="-0.01414 -0.01947 0.005"/>
  </joint>
  <!---Back part of the wheel -->
  <link name="roller_upback_rim_back_link">
    <inertial>
      <mass value="0.001"/>
      <inertia ixx="3.976186554728152e-08" ixy="0" ixz="0" iyy="3.976186554728152e-08" iyz="0" izz="2.092071223656384e-08"/>
    </inertial>
    <visual>
      <geometry>
        <mesh filename="package://erobotica_omnibot/mesh/rolamento.stl"/>
      </geometry>
      <material name="roller_material">
        <color rgba="0.1 0.1 0.1 1"/>
      </material>
    </visual>
    <collision>
      <geometry>
        <mesh filename="package://erobotica_omnibot/mesh/rolamento.stl"/>
      </geometry>
    </collision>
  </link>
  <gazebo reference="roller_upback_rim_back_link">
    <material>Gazebo/Black</material>
  </gazebo>
  <joint name="roller_upback_rim_back_joint" type="continuous">
    <parent link="rim_back_link"/>
    <child link="roller_upback_rim_back_link"/>
    <axis xyz="0 0 1"/>
    <origin rpy="-1.570796326794896 0 1.570796326794896" xyz="0 -0.02406 -0.006"/>
  </joint>
  <link name="roller_rightupback_rim_back_link">
    <inertial>
      <mass value="0.001"/>
      <inertia ixx="3.976186554728152e-08" ixy="0" ixz="0" iyy="3.976186554728152e-08" iyz="0" izz="2.092071223656384e-08"/>
    </inertial>
    <visual>
      <geometry>
        <mesh filename="package://erobotica_omnibot/mesh/rolamento.stl"/>
      </geometry>
      <material name="roller_material">
        <color rgba="0.1 0.1 0.1 1"/>
      </material>
    </visual>
    <collision>
      <geometry>
        <mesh filename="package://erobotica_omnibot/mesh/rolamento.stl"/>
      </geometry>
    </collision>
  </link>
  <gazebo reference="roller_rightupback_rim_back_link">
    <material>Gazebo/Black</material>
  </gazebo>
  <joint name="roller_rightupback_rim_back_joint" type="continuous">
    <parent link="rim_back_link"/>
    <child link="roller_rightupback_rim_back_link"/>
    <axis xyz="0 0 1"/>
    <origin rpy="-1.570796326794896 0 -2.82743" xyz=" -0.02288 -0.00743 -0.006"/>
  </joint>
  <link name="roller_leftupback_rim_back_link">
    <inertial>
      <mass value="0.001"/>
      <inertia ixx="3.976186554728152e-08" ixy="0" ixz="0" iyy="3.976186554728152e-08" iyz="0" izz="2.092071223656384e-08"/>
    </inertial>
    <visual>
      <geometry>
        <mesh filename="package://erobotica_omnibot/mesh/rolamento.stl"/>
      </geometry>
      <material name="roller_material">
        <color rgba="0.1 0.1 0.1 1"/>
      </material>
    </visual>
    <collision>
      <geometry>
        <mesh filename="package://erobotica_omnibot/mesh/rolamento.stl"/>
      </geometry>
    </collision>
  </link>
  <gazebo reference="roller_leftupback_rim_back_link">
    <material>Gazebo/Black</material>
  </gazebo>
  <joint name="roller_leftupback_rim_back_joint" type="continuous">
    <parent link="rim_back_link"/>
    <child link="roller_leftupback_rim_back_link"/>
    <axis xyz="0 0 1"/>
    <origin rpy="-1.570796326794896 0 2.82743" xyz=" 0.02288 -0.00743 -0.006"/>
  </joint>
  <link name="roller_rightdownback_rim_back_link">
    <inertial>
      <mass value="0.001"/>
      <inertia ixx="3.976186554728152e-08" ixy="0" ixz="0" iyy="3.976186554728152e-08" iyz="0" izz="2.092071223656384e-08"/>
    </inertial>
    <visual>
      <geometry>
        <mesh filename="package://erobotica_omnibot/mesh/rolamento.stl"/>
      </geometry>
      <material name="roller_material">
        <color rgba="0.1 0.1 0.1 1"/>
      </material>
    </visual>
    <collision>
      <geometry>
        <mesh filename="package://erobotica_omnibot/mesh/rolamento.stl"/>
      </geometry>
    </collision>
  </link>
  <gazebo reference="roller_rightdownback_rim_back_link">
    <material>Gazebo/Black</material>
  </gazebo>
  <joint name="roller_rightdownback_rim_back_joint" type="continuous">
    <parent link="rim_back_link"/>
    <child link="roller_rightdownback_rim_back_link"/>
    <axis xyz="0 0 1"/>
    <origin rpy="-1.570796326794896 0 -0.959931" xyz="-0.01414 0.01947 -0.006"/>
  </joint>
  <link name="roller_lefttdownback_rim_back_link">
    <inertial>
      <mass value="0.001"/>
      <inertia ixx="3.976186554728152e-08" ixy="0" ixz="0" iyy="3.976186554728152e-08" iyz="0" izz="2.092071223656384e-08"/>
    </inertial>
    <visual>
      <geometry>
        <mesh filename="package://erobotica_omnibot/mesh/rolamento.stl"/>
      </geometry>
      <material name="roller_material">
        <color rgba="0.1 0.1 0.1 1"/>
      </material>
    </visual>
    <collision>
      <geometry>
        <mesh filename="package://erobotica_omnibot/mesh/rolamento.stl"/>
      </geometry>
    </collision>
  </link>
  <gazebo reference="roller_lefttdownback_rim_back_link">
    <material>Gazebo/Black</material>
  </gazebo>
  <joint name="roller_lefttdownback_rim_back_joint" type="continuous">
    <parent link="rim_back_link"/>
    <child link="roller_lefttdownback_rim_back_link"/>
    <axis xyz="0 0 1"/>
    <origin rpy="-1.570796326794896 0 0.959931" xyz="0.01414  0.01947 -0.006"/>
  </joint>
  <transmission name="rim_back_transmission">
    <type>transmission_interface/SimpleTransmission</type>
    <joint name="rim_back_joint">
      <hardwareInterface>hardware_interface/VelocityJointInterface</hardwareInterface>
    </joint>
    <actuator name="rim_back_motor">
      <hardwareInterface>hardware_interface/VelocityJointInterface</hardwareInterface>
      <mechanicalReduction>1</mechanicalReduction>
    </actuator>
  </transmission>
  <link name="rim_right_link">
    <inertial>
      <origin xyz="0 0 -0.000343"/>
      <mass value="0.083"/>
      <inertia ixx="0.1449e-04" ixy="0" ixz="0" iyy="0.1449e-04" iyz="0" izz="0.2283e-04"/>
    </inertial>
    <visual>
      <geometry>
        <mesh filename="package://erobotica_omnibot/mesh/roda.stl"/>
      </geometry>
      <material name="rim_right_material">
        <color rgba="0 0 0.3 1"/>
      </material>
    </visual>
    <collision>
      <!---test -->
      <geometry>
        <!---<cylinder length="0.6" radius="0.029"/> -->
        <mesh filename="package://erobotica_omnibot/mesh/roda.stl"/>
      </geometry>
    </collision>
  </link>
  <joint name="rim_right_joint" type="continuous">
    <parent link="base_link"/>
    <child link="rim_right_link"/>
    <axis xyz="0 0 1"/>
    <origin rpy="1.570796326794896 0 -1.047197551196597" xyz="0.0893842140 0.051606 0.020269"/>
  </joint>
  <link name="roller_upfront_rim_right_link">
    <inertial>
      <mass value="0.001"/>
      <inertia ixx="3.976186554728152e-08" ixy="0" ixz="0" iyy="3.976186554728152e-08" iyz="0" izz="2.092071223656384e-08"/>
    </inertial>
    <visual>
      <geometry>
        <mesh filename="package://erobotica_omnibot/mesh/rolamento.stl"/>
      </geometry>
      <material name="roller_material">
        <color rgba="0.1 0.1 0.1 1"/>
      </material>
    </visual>
    <collision>
      <geometry>
        <mesh filename="package://erobotica_omnibot/mesh/rolamento.stl"/>
      </geometry>
    </collision>
  </link>
  <gazebo reference="roller_upfront_rim_right_link">
    <material>Gazebo/Black</material>
  </gazebo>
  <joint name="roller_upfront_rim_right_joint" type="continuous">
    <parent link="rim_right_link"/>
    <child link="roller_upfront_rim_right_link"/>
    <axis xyz="0 0 1"/>
    <origin rpy="-1.570796326794896 0 1.570796326794896" xyz="0 0.02406 0.005"/>
  </joint>
  <link name="roller_rightupfront_rim_right_link">
    <inertial>
      <mass value="0.001"/>
      <inertia ixx="3.976186554728152e-08" ixy="0" ixz="0" iyy="3.976186554728152e-08" iyz="0" izz="2.092071223656384e-08"/>
    </inertial>
    <visual>
      <geometry>
        <mesh filename="package://erobotica_omnibot/mesh/rolamento.stl"/>
      </geometry>
      <material name="roller_material">
        <color rgba="0.1 0.1 0.1 1"/>
      </material>
    </visual>
    <collision>
      <geometry>
        <mesh filename="package://erobotica_omnibot/mesh/rolamento.stl"/>
      </geometry>
    </collision>
  </link>
  <gazebo reference="roller_rightupfront_rim_right_link">
    <material>Gazebo/Black</material>
  </gazebo>
  <joint name="roller_rightupfront_rim_right_joint" type="continuous">
    <parent link="rim_right_link"/>
    <child link="roller_rightupfront_rim_right_link"/>
    <axis xyz="0 0 1"/>
    <origin rpy="-1.570796326794896 0 -2.82743" xyz=" 0.02288 0.00743 0.005"/>
  </joint>
  <link name="roller_leftupfront_rim_right_link">
    <inertial>
      <mass value="0.001"/>
      <inertia ixx="3.976186554728152e-08" ixy="0" ixz="0" iyy="3.976186554728152e-08" iyz="0" izz="2.092071223656384e-08"/>
    </inertial>
    <visual>
      <geometry>
        <mesh filename="package://erobotica_omnibot/mesh/rolamento.stl"/>
      </geometry>
      <material name="roller_material">
        <color rgba="0.1 0.1 0.1 1"/>
      </material>
    </visual>
    <collision>
      <geometry>
        <mesh filename="package://erobotica_omnibot/mesh/rolamento.stl"/>
      </geometry>
    </collision>
  </link>
  <gazebo reference="roller_leftupfront_rim_right_link">
    <material>Gazebo/Black</material>
  </gazebo>
  <joint name="roller_leftupfront_rim_right_joint" type="continuous">
    <parent link="rim_right_link"/>
    <child link="roller_leftupfront_rim_right_link"/>
    <axis xyz="0 0 1"/>
    <origin rpy="-1.570796326794896 0 2.82743" xyz=" -0.02288  0.00743 0.005"/>
  </joint>
  <link name="roller_rightdownfront_rim_right_link">
    <inertial>
      <mass value="0.001"/>
      <inertia ixx="3.976186554728152e-08" ixy="0" ixz="0" iyy="3.976186554728152e-08" iyz="0" izz="2.092071223656384e-08"/>
    </inertial>
    <visual>
      <geometry>
        <mesh filename="package://erobotica_omnibot/mesh/rolamento.stl"/>
      </geometry>
      <material name="roller_material">
        <color rgba="0.1 0.1 0.1 1"/>
      </material>
    </visual>
    <collision>
      <geometry>
        <mesh filename="package://erobotica_omnibot/mesh/rolamento.stl"/>
      </geometry>
    </collision>
  </link>
  <gazebo reference="roller_rightdownfront_rim_right_link">
    <material>Gazebo/Black</material>
  </gazebo>
  <joint name="roller_rightdownfront_rim_right_joint" type="continuous">
    <parent link="rim_right_link"/>
    <child link="roller_rightdownfront_rim_right_link"/>
    <axis xyz="0 0 1"/>
    <origin rpy="-1.570796326794896 0 -0.959931" xyz="0.01414 -0.01947 0.005"/>
  </joint>
  <link name="roller_lefttdownfront_rim_right_link">
    <inertial>
      <mass value="0.001"/>
      <inertia ixx="3.976186554728152e-08" ixy="0" ixz="0" iyy="3.976186554728152e-08" iyz="0" izz="2.092071223656384e-08"/>
    </inertial>
    <visual>
      <geometry>
        <mesh filename="package://erobotica_omnibot/mesh/rolamento.stl"/>
      </geometry>
      <material name="roller_material">
        <color rgba="0.1 0.1 0.1 1"/>
      </material>
    </visual>
    <collision>
      <geometry>
        <mesh filename="package://erobotica_omnibot/mesh/rolamento.stl"/>
      </geometry>
    </collision>
  </link>
  <gazebo reference="roller_lefttdownfront_rim_right_link">
    <material>Gazebo/Black</material>
  </gazebo>
  <joint name="roller_lefttdownfront_rim_right_joint" type="continuous">
    <parent link="rim_right_link"/>
    <child link="roller_lefttdownfront_rim_right_link"/>
    <axis xyz="0 0 1"/>
    <origin rpy="-1.570796326794896 0 0.959931" xyz="-0.01414 -0.01947 0.005"/>
  </joint>
  <!---Back part of the wheel -->
  <link name="roller_upback_rim_right_link">
    <inertial>
      <mass value="0.001"/>
      <inertia ixx="3.976186554728152e-08" ixy="0" ixz="0" iyy="3.976186554728152e-08" iyz="0" izz="2.092071223656384e-08"/>
    </inertial>
    <visual>
      <geometry>
        <mesh filename="package://erobotica_omnibot/mesh/rolamento.stl"/>
      </geometry>
      <material name="roller_material">
        <color rgba="0.1 0.1 0.1 1"/>
      </material>
    </visual>
    <collision>
      <geometry>
        <mesh filename="package://erobotica_omnibot/mesh/rolamento.stl"/>
      </geometry>
    </collision>
  </link>
  <gazebo reference="roller_upback_rim_right_link">
    <material>Gazebo/Black</material>
  </gazebo>
  <joint name="roller_upback_rim_right_joint" type="continuous">
    <parent link="rim_right_link"/>
    <child link="roller_upback_rim_right_link"/>
    <axis xyz="0 0 1"/>
    <origin rpy="-1.570796326794896 0 1.570796326794896" xyz="0 -0.02406 -0.006"/>
  </joint>
  <link name="roller_rightupback_rim_right_link">
    <inertial>
      <mass value="0.001"/>
      <inertia ixx="3.976186554728152e-08" ixy="0" ixz="0" iyy="3.976186554728152e-08" iyz="0" izz="2.092071223656384e-08"/>
    </inertial>
    <visual>
      <geometry>
        <mesh filename="package://erobotica_omnibot/mesh/rolamento.stl"/>
      </geometry>
      <material name="roller_material">
        <color rgba="0.1 0.1 0.1 1"/>
      </material>
    </visual>
    <collision>
      <geometry>
        <mesh filename="package://erobotica_omnibot/mesh/rolamento.stl"/>
      </geometry>
    </collision>
  </link>
  <gazebo reference="roller_rightupback_rim_right_link">
    <material>Gazebo/Black</material>
  </gazebo>
  <joint name="roller_rightupback_rim_right_joint" type="continuous">
    <parent link="rim_right_link"/>
    <child link="roller_rightupback_rim_right_link"/>
    <axis xyz="0 0 1"/>
    <origin rpy="-1.570796326794896 0 -2.82743" xyz=" -0.02288 -0.00743 -0.006"/>
  </joint>
  <link name="roller_leftupback_rim_right_link">
    <inertial>
      <mass value="0.001"/>
      <inertia ixx="3.976186554728152e-08" ixy="0" ixz="0" iyy="3.976186554728152e-08" iyz="0" izz="2.092071223656384e-08"/>
    </inertial>
    <visual>
      <geometry>
        <mesh filename="package://erobotica_omnibot/mesh/rolamento.stl"/>
      </geometry>
      <material name="roller_material">
        <color rgba="0.1 0.1 0.1 1"/>
      </material>
    </visual>
    <collision>
      <geometry>
        <mesh filename="package://erobotica_omnibot/mesh/rolamento.stl"/>
      </geometry>
    </collision>
  </link>
  <gazebo reference="roller_leftupback_rim_right_link">
    <material>Gazebo/Black</material>
  </gazebo>
  <joint name="roller_leftupback_rim_right_joint" type="continuous">
    <parent link="rim_right_link"/>
    <child link="roller_leftupback_rim_right_link"/>
    <axis xyz="0 0 1"/>
    <origin rpy="-1.570796326794896 0 2.82743" xyz=" 0.02288 -0.00743 -0.006"/>
  </joint>
  <link name="roller_rightdownback_rim_right_link">
    <inertial>
      <mass value="0.001"/>
      <inertia ixx="3.976186554728152e-08" ixy="0" ixz="0" iyy="3.976186554728152e-08" iyz="0" izz="2.092071223656384e-08"/>
    </inertial>
    <visual>
      <geometry>
        <mesh filename="package://erobotica_omnibot/mesh/rolamento.stl"/>
      </geometry>
      <material name="roller_material">
        <color rgba="0.1 0.1 0.1 1"/>
      </material>
    </visual>
    <collision>
      <geometry>
        <mesh filename="package://erobotica_omnibot/mesh/rolamento.stl"/>
      </geometry>
    </collision>
  </link>
  <gazebo reference="roller_rightdownback_rim_right_link">
    <material>Gazebo/Black</material>
  </gazebo>
  <joint name="roller_rightdownback_rim_right_joint" type="continuous">
    <parent link="rim_right_link"/>
    <child link="roller_rightdownback_rim_right_link"/>
    <axis xyz="0 0 1"/>
    <origin rpy="-1.570796326794896 0 -0.959931" xyz="-0.01414 0.01947 -0.006"/>
  </joint>
  <link name="roller_lefttdownback_rim_right_link">
    <inertial>
      <mass value="0.001"/>
      <inertia ixx="3.976186554728152e-08" ixy="0" ixz="0" iyy="3.976186554728152e-08" iyz="0" izz="2.092071223656384e-08"/>
    </inertial>
    <visual>
      <geometry>
        <mesh filename="package://erobotica_omnibot/mesh/rolamento.stl"/>
      </geometry>
      <material name="roller_material">
        <color rgba="0.1 0.1 0.1 1"/>
      </material>
    </visual>
    <collision>
      <geometry>
        <mesh filename="package://erobotica_omnibot/mesh/rolamento.stl"/>
      </geometry>
    </collision>
  </link>
  <gazebo reference="roller_lefttdownback_rim_right_link">
    <material>Gazebo/Black</material>
  </gazebo>
  <joint name="roller_lefttdownback_rim_right_joint" type="continuous">
    <parent link="rim_right_link"/>
    <child link="roller_lefttdownback_rim_right_link"/>
    <axis xyz="0 0 1"/>
    <origin rpy="-1.570796326794896 0 0.959931" xyz="0.01414  0.01947 -0.006"/>
  </joint>
  <transmission name="rim_right_transmission">
    <type>transmission_interface/SimpleTransmission</type>
    <joint name="rim_right_joint">
      <hardwareInterface>hardware_interface/VelocityJointInterface</hardwareInterface>
    </joint>
    <actuator name="rim_right_motor">
      <hardwareInterface>hardware_interface/VelocityJointInterface</hardwareInterface>
      <mechanicalReduction>1</mechanicalReduction>
    </actuator>
  </transmission>
  <gazebo reference="base_link">
    <material>Gazebo/White</material>
  </gazebo>
  <gazebo reference="rim_left_link">
    <material>Gazebo/Red</material>
  </gazebo>
  <gazebo reference="rim_back_link">
    <material>Gazebo/Green</material>
  </gazebo>
  <gazebo reference="rim_right_link">
    <material>Gazebo/Blue</material>
  </gazebo>
  <gazebo>
    <plugin filename="libgazebo_ros_control.so" name="gazebo_ros_control">
      <robotNamespace>/open_base</robotNamespace>
    </plugin>
  </gazebo>
</robot>

